Workbook

Sheet 1.Supuestos
A1: TABLA C — MODELO RENTISTA | SUPUESTOS Y FUENTES
A2: Aritmética 100% transparente | Autor: Danilo Daneri Solano | Asistente: Claudita
A4: Parámetro | B4: Valor | C4: Unidad | D4: Fuente
A5: DEMOGRAFÍA
A6: Cohorte nuevos jubilados/año | B6: 60000 | C6: personas | D6: Libro p.3788 · INE tablas mortalidad 2023
A7: Uniformados universo inicial | B7: 176536 | C7: personas | D7: Libro p.2409 · CIEDESS oct.2024
A8: Civiles AFP con brecha | B8: 328204 | C8: personas | D8: Libro p.4207 · Superint. Pensiones sep.2022
A9: Profesores (top-up) | B9: 200000 | C9: personas | D9: Libro p.4204 · CASEN 2022
A10: Pueblos originarios | B10: 100000 | C10: personas | D10: Libro p.4205 · INE CASEN 2022
A11: Grupos olvidados tramo 1 | B11: 500000 | C11: personas | D11: Libro Cap.12 · SERNAPESCA+ENAMI+INE
A12: Grupos olvidados tramo 2 | B12: 1000000 | C12: personas | D12: Libro Cap.12 · feriantes, cuidadoras, etc.
A13: Sin ahorro previsional (65+) | B13: 476181 | C13: personas | D13: Libro p.4206 · SP/USS abr.2024
A14: FINANCIEROS
A15: Tasa retorno real AFJ | B15: 0.05 | C15: % anual | D15: Libro p.3590 (Regla ×240 al 5%)
A16: IPC proyectado | B16: 0.035 | C16: % anual | D16: Libro p.3594 · BCCh meta inflación
A17: Tasa nominal AFJ (IPC+real) | B17: 0.085 | C17: % anual | D17: Libro p.3594
A18: Fracción B1 (crédito fundado) | B18: 0.3 | C18: % del fondo | D18: Libro · Regla 30/30/40
A19: Tope fisco dentro de B1 | B19: 0.25 | C19: % de B1 | D19: Libro p.3511 (25% del 30%)
A20: Fracción prestable al fisco | B20: 0.075 | C20: % del fondo | D20: Cálculo: 30% × 25%
A21: PGU Y GASTOS FISCALES
A22: PGU feb 2026 | B22: 231732 | C22: $/mes | D22: IPS feb.2026
A23: PGU sep 2026 (Ley 21.735) | B23: 250275 | C23: $/mes | D23: Ley 21.735 · ChileAtiende
A24: Gasto fiscal uniformados | B24: 2.9 | C24: billones/año | D24: BCN/DIPRES Presup.2026
A25: Gasto BAC+CEV régimen | B25: 1.5 | C25: billones/año | D25: DIPRES dic.2025
A26: Otros beneficios Seg.Soc. | B26: 1.02 | C26: billones/año | D26: BCN Presup.2026 (Ley 20.531)
A27: CAPITAL INICIAL POR GRUPO
A28: Capital uniformados | B28: 47.9 | C28: billones | D28: Libro p.4203
A29: Capital civiles AFP brecha | B29: 35.3 | C29: billones | D29: Libro p.4207
A30: Capital profesores | B30: 19.2 | C30: billones | D30: Libro p.4204
A31: Capital pueblos originarios | B31: 9.6 | C31: billones | D31: Libro p.4205
A32: Capital sin ahorro (65+) | B32: 61.6 | C32: billones | D32: Libro p.4206
A33: Capital grupos olvidados | B33: 30 | C33: billones | D33: Libro Cap.12 estimado
A34: Capital por nuevo jubilado | B34: 0.10736 | C34: billones | D34: Libro p.3788 ($107,36 MM × 240)
A35: MACRO (2026)
A36: PIB Chile 2026 | B36: 361 | C36: billones | D36: DIPRES IFP 4T 2025 (23,8% = $85,8B)
A37: Crecimiento PIB nominal | B37: 0.058 | C37: % anual | D37: DIPRES 2,3% real + 3,5% IPC
A38: Presupuesto Chile 2026 | B38: 86.2 | C38: billones | D38: DIPRES/Hacienda ley aprobada nov.2025
A41: LEYENDA DE COLORES
A42: Azul: Input (valor hardcodeado)
A43: Negro: Fórmula calculada
...

Sheet 2.Tabla C (30 años)
A1: TABLA C — BENEFICIO AL ESTADO AÑO A AÑO (30 años)
A2: Cifras en billones de pesos nominales | Todos los cálculos por fórmula | Links a 1.Supuestos en verde
B4: FONDO AFJ | D4: AHORRO FISCAL POR GRUPO (anual) | J4: AHORRO FISCAL CONSOLIDADO | L4: BENEFICIO TOTAL | O4: AUXILIARES
A5: Año | B5: Fondo (bill) | C5: Prestable 7,5% (bill) | D5: Unif (bill) | E5: Civiles (bill) | F5: Prof+PO (bill) | G5: Olvidados (bill) | H5: SinAhorro (bill) | I5: Otros (bill) | J5: Total anual | K5: Acumulado | L5: Benef. Total | M5: PIB (bill) | N5: % PIB | O5: PGU unit. ($ anual) | P5: Originación acum (bill)
A6: 1 | B6: =P6*(1+'1.Supuestos'!$B$16)^MAX(0,A6-1)+'1.Supuestos'!$B$6*107360000/1000000000000*A6 -> 54.3416 | C6: =B6*'1.Supuestos'!$B$20 -> 4.07562 | D6: =IF(A6>=1,'1.Supuestos'!$B$24*(1+'1.Supuestos'!$B$16)^(A6-1),0) -> 2.9 | E6: =IF(A6>=2,'1.Supuestos'!$B$8*O6/1000000000000,0) -> 0 | F6: =IF(A6>=3,('1.Supuestos'!$B$9+'1.Supuestos'!$B$10)*O6/1000000000000,0) -> 0 | G6: =IF(A6>=4,'1.Supuestos'!$B$11*O6/1000000000000,0)+IF(A6>=5,'1.Supuestos'!$B$12*O6/1000000000000,0) -> 0 | H6: =IF(A6>=5,'1.Supuestos'!$B$13*O6/1000000000000,0) -> 0 | I6: =IF(A6>=2,('1.Supuestos'!$B$25+'1.Supuestos'!$B$26)*MIN(1,(A6-1)/5)*(1+'1.Supuestos'!$B$16)^(A6-1),0) -> 0 | J6: =SUM(D6:I6) -> 2.9 | K6: =J6 -> 2.9 | L6: =C6+K6 -> 6.97562 | M6: ='1.Supuestos'!$B$36*(1+'1.Supuestos'!$B$37)^(A6-1) -> 361 | N6: =L6/M6 -> 0.019323047 | O6: ='1.Supuestos'!$B$22*12 -> 2780784 | P6: =IF(A6>=1,'1.Supuestos'!$B$28,0)+IF(A6>=2,'1.Supuestos'!$B$29,0)+IF(A6>=3,'1.Supuestos'!$B$30+'1.Supuestos'!$B$31,0)+IF(A6>=4,'1.Supuestos'!$B$33*0.5,0)+IF(A6>=5,'1.Supuestos'!$B$33*0.5+'1.Supuestos'!$B$32,0) -> 47.9
A7: 2 | B7: =P7*(1+'1.Supuestos'!$B$16)^MAX(0,A7-1)+'1.Supuestos'!$B$6*107360000/1000000000000*A7 -> 98.9952 | C7: =B7*'1.Supuestos'!$B$20 -> 7.42464 | D7: =IF(A7>=1,'1.Supuestos'!$B$24*(1+'1.Supuestos'!$B$16)^(A7-1),0) -> 3.0015 | E7: =IF(A7>=2,'1.Supuestos'!$B$8*O7/1000000000000,0) -> 1.0201944 | F7: =IF(A7>=3,('1.Supuestos'!$B$9+'1.Supuestos'!$B$10)*O7/1000000000000,0) -> 0 | G7: =IF(A7>=4,'1.Supuestos'!$B$11*O7/1000000000000,0)+IF(A7>=5,'1.Supuestos'!$B$12*O7/1000000000000,0) -> 0 | H7: =IF(A7>=5,'1.Supuestos'!$B$13*O7/1000000000000,0) -> 0 | I7: =IF(A7>=2,('1.Supuestos'!$B$25+'1.Supuestos'!$B$26)*MIN(1,(A7-1)/5)*(1+'1.Supuestos'!$B$16)^(A7-1),0) -> 0.52164 | J7: =SUM(D7:I7) -> 4.5433344 | K7: =K6+J7 -> 7.4433344 | L7: =C7+K7 -> 14.867974 | M7: ='1.Supuestos'!$B$36*(1+'1.Supuestos'!$B$37)^(A7-1) -> 381.938 | N7: =L7/M7 -> 0.038927717 | O7: ='1.Supuestos'!$B$23*12*(1+'1.Supuestos'!$B$16)^(A7-1) -> 3108415.5 | P7: =IF(A7>=1,'1.Supuestos'!$B$28,0)+IF(A7>=2,'1.Supuestos'!$B$29,0)+IF(A7>=3,'1.Supuestos'!$B$30+'1.Supuestos'!$B$31,0)+IF(A7>=4,'1.Supuestos'!$B$33*0.5,0)+IF(A7>=5,'1.Supuestos'!$B$33*0.5+'1.Supuestos'!$B$32,0) -> 83.2
A8: 3 | B8: =P8*(1+'1.Supuestos'!$B$16)^MAX(0,A8-1)+'1.Supuestos'!$B$6*107360000/1000000000000*A8 -> 139.302 | C8: =B8*'1.Supuestos'!$B$20 -> 10.44765 | D8: =IF(A8>=1,'1.Supuestos'!$B$24*(1+'1.Supuestos'!$B$16)^(A8-1),0) -> 3.1065525 | E8: =IF(A8>=2,'1.Supuestos'!$B$8*O8/1000000000000,0) -> 1.0559012 | F8: =IF(A8>=3,('1.Supuestos'!$B$9+'1.Supuestos'!$B$10)*O8/1000000000000,0) -> 0.96516301 | G8: =IF(A8>=4,'1.Supuestos'!$B$11*O8/1000000000000,0)+IF(A8>=5,'1.Supuestos'!$B$12*O8/1000000000000,0) -> 0 | H8: =IF(A8>=5,'1.Supuestos'!$B$13*O8/1000000000000,0) -> 0 | I8: =IF(A8>=2,('1.Supuestos'!$B$25+'1.Supuestos'!$B$26)*MIN(1,(A8-1)/5)*(1+'1.Supuestos'!$B$16)^(A8-1),0) -> 1.0797948 | J8: =SUM(D8:I8) -> 6.2074115 | K8: =K7+J8 -> 13.650746 | L8: =C8+K8 -> 24.098396 | M8: ='1.Supuestos'!$B$36*(1+'1.Supuestos'!$B$37)^(A8-1) -> 404.0904 | N8: =L8/M8 -> 0.05963615 | O8: ='1.Supuestos'!$B$23*12*(1+'1.Supuestos'!$B$16)^(A8-1) -> 3217210 | P8: =IF(A8>=1,'1.Supuestos'!$B$28,0)+IF(A8>=2,'1.Supuestos'!$B$29,0)+IF(A8>=3,'1.Supuestos'!$B$30+'1.Supuestos'!$B$31,0)+IF(A8>=4,'1.Supuestos'!$B$33*0.5,0)+IF(A8>=5,'1.Supuestos'!$B$33*0.5+'1.Supuestos'!$B$32,0) -> 112
A9: 4 | B9: =P9*(1+'1.Supuestos'!$B$16)^MAX(0,A9-1)+'1.Supuestos'!$B$6*107360000/1000000000000*A9 -> 166.57357 | C9: =B9*'1.Supuestos'!$B$20 -> 12.493018 | D9: =IF(A9>=1,'1.Supuestos'!$B$24*(1+'1.Supuestos'!$B$16)^(A9-1),0) -> 3.2152818 | E9: =IF(A9>=2,'1.Supuestos'!$B$8*O9/1000000000000,0) -> 1.0928577 | F9: =IF(A9>=3,('1.Supuestos'!$B$9+'1.Supuestos'!$B$10)*O9/1000000000000,0) -> 0.99894372 | G9: =IF(A9>=4,'1.Supuestos'!$B$11*O9/1000000000000,0)+IF(A9>=5,'1.Supuestos'!$B$12*O9/1000000000000,0) -> 1.6649062 | H9: =IF(A9>=5,'1.Supuestos'!$B$13*O9/1000000000000,0) -> 0 | I9: =IF(A9>=2,('1.Supuestos'!$B$25+'1.Supuestos'!$B$26)*MIN(1,(A9-1)/5)*(1+'1.Supuestos'!$B$16)^(A9-1),0) -> 1.6763814 | J9: =SUM(D9:I9) -> 8.6483709 | K9: =K8+J9 -> 22.299117 | L9: =C9+K9 -> 34.792135 | M9: ='1.Supuestos'!$B$36*(1+'1.Supuestos'!$B$37)^(A9-1) -> 427.52765 | N9: =L9/M9 -> 0.081379847 | O9: ='1.Supuestos'!$B$23*12*(1+'1.Supuestos'!$B$16)^(A9-1) -> 3329812.4 | P9: =IF(A9>=1,'1.Supuestos'!$B$28,0)+IF(A9>=2,'1.Supuestos'!$B$29,0)+IF(A9>=3,'1.Supuestos'!$B$30+'1.Supuestos'!$B$31,0)+IF(A9>=4,'1.Supuestos'!$B$33*0.5,0)+IF(A9>=5,'1.Supuestos'!$B$33*0.5+'1.Supuestos'!$B$32,0) -> 127
A10: 5 | B10: =P10*(1+'1.Supuestos'!$B$16)^MAX(0,A10-1)+'1.Supuestos'!$B$6*107360000/1000000000000*A10 -> 265.84368 | C10: =B10*'1.Supuestos'!$B$20 -> 19.938276 | D10: =IF(A10>=1,'1.Supuestos'!$B$24*(1+'1.Supuestos'!$B$16)^(A10-1),0) -> 3.3278167 | E10: =IF(A10>=2,'1.Supuestos'!$B$8*O10/1000000000000,0) -> 1.1311078 | F10: =IF(A10>=3,('1.Supuestos'!$B$9+'1.Supuestos'!$B$10)*O10/1000000000000,0) -> 1.0339067 | G10: =IF(A10>=4,'1.Supuestos'!$B$11*O10/1000000000000,0)+IF(A10>=5,'1.Supuestos'!$B$12*O10/1000000000000,0) -> 5.1695337 | H10: =IF(A10>=5,'1.Supuestos'!$B$13*O10/1000000000000,0) -> 1.6410892 | I10: =IF(A10>=2,('1.Supuestos'!$B$25+'1.Supuestos'!$B$26)*MIN(1,(A10-1)/5)*(1+'1.Supuestos'!$B$16)^(A10-1),0) -> 2.3134064 | J10: =SUM(D10:I10) -> 14.61686 | K10: =K9+J10 -> 36.915977 | L10: =C10+K10 -> 56.854254 | M10: ='1.Supuestos'!$B$36*(1+'1.Supuestos'!$B$37)^(A10-1) -> 452.32425 | N10: =L10/M10 -> 0.12569358 | O10: ='1.Supuestos'!$B$23*12*(1+'1.Supuestos'!$B$16)^(A10-1) -> 3446355.8 | P10: =IF(A10>=1,'1.Supuestos'!$B$28,0)+IF(A10>=2,'1.Supuestos'!$B$29,0)+IF(A10>=3,'1.Supuestos'!$B$30+'1.Supuestos'!$B$31,0)+IF(A10>=4,'1.Supuestos'!$B$33*0.5,0)+IF(A10>=5,'1.Supuestos'!$B$33*0.5+'1.Supuestos'!$B$32,0) -> 203.6
A11: 6 | B11: =P11*(1+'1.Supuestos'!$B$16)^MAX(0,A11-1)+'1.Supuestos'!$B$6*107360000/1000000000000*A11 -> 280.46253 | C11: =B11*'1.Supuestos'!$B$20 -> 21.03469 | D11: =IF(A11>=1,'1.Supuestos'!$B$24*(1+'1.Supuestos'!$B$16)^(A11-1),0) -> 3.4442903 | E11: =IF(A11>=2,'1.Supuestos'!$B$8*O11/1000000000000,0) -> 1.1706965 | F11: =IF(A11>=3,('1.Supuestos'!$B$9+'1.Supuestos'!$B$10)*O11/1000000000000,0) -> 1.0700935 | G11: =IF(A11>=4,'1.Supuestos'!$B$11*O11/1000000000000,0)+IF(A11>=5,'1.Supuestos'!$B$12*O11/1000000000000,0) -> 5.3504674 | H11: =IF(A11>=5,'1.Supuestos'!$B$13*O11/1000000000000,0) -> 1.6985273 | I11: =IF(A11>=2,('1.Supuestos'!$B$25+'1.Supuestos'!$B$26)*MIN(1,(A11-1)/5)*(1+'1.Supuestos'!$B$16)^(A11-1),0) -> 2.9929695 | J11: =SUM(D11:I11) -> 15.727045 | K11: =K10+J11 -> 52.643022 | L11: =C11+K11 -> 73.677712 | M11: ='1.Supuestos'!$B$36*(1+'1.Supuestos'!$B$37)^(A11-1) -> 478.55906 | N11: =L11/M11 -> 0.15395741 | O11: ='1.Supuestos'!$B$23*12*(1+'1.Supuestos'!$B$16)^(A11-1) -> 3566978.3 | P11: =IF(A11>=1,'1.Supuestos'!$B$28,0)+IF(A11>=2,'1.Supuestos'!$B$29,0)+IF(A11>=3,'1.Supuestos'!$B$30+'1.Supuestos'!$B$31,0)+IF(A11>=4,'1.Supuestos'!$B$33*0.5,0)+IF(A11>=5,'1.Supuestos'!$B$33*0.5+'1.Supuestos'!$B$32,0) -> 203.6
A12: 7 | B12: =P12*(1+'1.Supuestos'!$B$16)^MAX(0,A12-1)+'1.Supuestos'!$B$6*107360000/1000000000000*A12 -> 295.36758 | C12: =B12*'1.Supuestos'!$B$20 -> 22.152569 | D12: =IF(A12>=1,'1.Supuestos'!$B$24*(1+'1.Supuestos'!$B$16)^(A12-1),0) -> 3.5648404 | E12: =IF(A12>=2,'1.Supuestos'!$B$8*O12/1000000000000,0) -> 1.2116709 | F12: =IF(A12>=3,('1.Supuestos'!$B$9+'1.Supuestos'!$B$10)*O12/1000000000000,0) -> 1.1075468 | G12: =IF(A12>=4,'1.Supuestos'!$B$11*O12/1000000000000,0)+IF(A12>=5,'1.Supuestos'!$B$12*O12/1000000000000,0) -> 5.5377338 | H12: =IF(A12>=5,'1.Supuestos'!$B$13*O12/1000000000000,0) -> 1.7579757 | I12: =IF(A12>=2,('1.Supuestos'!$B$25+'1.Supuestos'!$B$26)*MIN(1,(A12-1)/5)*(1+'1.Supuestos'!$B$16)^(A12-1),0) -> 3.0977234 | J12: =SUM(D12:I12) -> 16.277491 | K12: =K11+J12 -> 68.920513 | L12: =C12+K12 -> 91.073082 | M12: ='1.Supuestos'!$B$36*(1+'1.Supuestos'!$B$37)^(A12-1) -> 506.31548 | N12: =L12/M12 -> 0.17987418 | O12: ='1.Supuestos'!$B$23*12*(1+'1.Supuestos'!$B$16)^(A12-1) -> 3691822.5 | P12: =IF(A12>=1,'1.Supuestos'!$B$28,0)+IF(A12>=2,'1.Supuestos'!$B$29,0)+IF(A12>=3,'1.Supuestos'!$B$30+'1.Supuestos'!$B$31,0)+IF(A12>=4,'1.Supuestos'!$B$33*0.5,0)+IF(A12>=5,'1.Supuestos'!$B$33*0.5+'1.Supuestos'!$B$32,0) -> 203.6
A13: 8 | B13: =P13*(1+'1.Supuestos'!$B$16)^MAX(0,A13-1)+'1.Supuestos'!$B$6*107360000/1000000000000*A13 -> 310.56886 | C13: =B13*'1.Supuestos'!$B$20 -> 23.292664 | D13: =IF(A13>=1,'1.Supuestos'!$B$24*(1+'1.Supuestos'!$B$16)^(A13-1),0) -> 3.6896099 | E13: =IF(A13>=2,'1.Supuestos'!$B$8*O13/1000000000000,0) -> 1.2540794 | F13: =IF(A13>=3,('1.Supuestos'!$B$9+'1.Supuestos'!$B$10)*O13/1000000000000,0) -> 1.1463109 | G13: =IF(A13>=4,'1.Supuestos'!$B$11*O13/1000000000000,0)+IF(A13>=5,'1.Supuestos'!$B$12*O13/1000000000000,0) -> 5.7315545 | H13: =IF(A13>=5,'1.Supuestos'!$B$13*O13/1000000000000,0) -> 1.8195049 | I13: =IF(A13>=2,('1.Supuestos'!$B$25+'1.Supuestos'!$B$26)*MIN(1,(A13-1)/5)*(1+'1.Supuestos'!$B$16)^(A13-1),0) -> 3.2061437 | J13: =SUM(D13:I13) -> 16.847203 | K13: =K12+J13 -> 85.767716 | L13: =C13+K13 -> 109.06038 | M13: ='1.Supuestos'!$B$36*(1+'1.Supuestos'!$B$37)^(A13-1) -> 535.68178 | N13: =L13/M13 -> 0.20359173 | O13: ='1.Supuestos'!$B$23*12*(1+'1.Supuestos'!$B$16)^(A13-1) -> 3821036.3 | P13: =IF(A13>=1,'1.Supuestos'!$B$28,0)+IF(A13>=2,'1.Supuestos'!$B$29,0)+IF(A13>=3,'1.Supuestos'!$B$30+'1.Supuestos'!$B$31,0)+IF(A13>=4,'1.Supuestos'!$B$33*0.5,0)+IF(A13>=5,'1.Supuestos'!$B$33*0.5+'1.Supuestos'!$B$32,0) -> 203.6
A14: 9 | B14: =P14*(1+'1.Supuestos'!$B$16)^MAX(0,A14-1)+'1.Supuestos'!$B$6*107360000/1000000000000*A14 -> 326.07672 | C14: =B14*'1.Supuestos'!$B$20 -> 24.455754 | D14: =IF(A14>=1,'1.Supuestos'!$B$24*(1+'1.Supuestos'!$B$16)^(A14-1),0) -> 3.8187462 | E14: =IF(A14>=2,'1.Supuestos'!$B$8*O14/1000000000000,0) -> 1.2979722 | F14: =IF(A14>=3,('1.Supuestos'!$B$9+'1.Supuestos'!$B$10)*O14/1000000000000,0) -> 1.1864318 | G14: =IF(A14>=4,'1.Supuestos'!$B$11*O14/1000000000000,0)+IF(A14>=5,'1.Supuestos'!$B$12*O14/1000000000000,0) -> 5.9321589 | H14: =IF(A14>=5,'1.Supuestos'!$B$13*O14/1000000000000,0) -> 1.8831876 | I14: =IF(A14>=2,('1.Supuestos'!$B$25+'1.Supuestos'!$B$26)*MIN(1,(A14-1)/5)*(1+'1.Supuestos'!$B$16)^(A14-1),0) -> 3.3183588 | J14: =SUM(D14:I14) -> 17.436855 | K14: =K13+J14 -> 103.20457 | L14: =C14+K14 -> 127.66033 | M14: ='1.Supuestos'!$B$36*(1+'1.Supuestos'!$B$37)^(A14-1) -> 566.75132 | N14: =L14/M14 -> 0.22524928 | O14: ='1.Supuestos'!$B$23*12*(1+'1.Supuestos'!$B$16)^(A14-1) -> 3954772.6 | P14: =IF(A14>=1,'1.Supuestos'!$B$28,0)+IF(A14>=2,'1.Supuestos'!$B$29,0)+IF(A14>=3,'1.Supuestos'!$B$30+'1.Supuestos'!$B$31,0)+IF(A14>=4,'1.Supuestos'!$B$33*0.5,0)+IF(A14>=5,'1.Supuestos'!$B$33*0.5+'1.Supuestos'!$B$32,0) -> 203.6
A15: 10 | B15: =P15*(1+'1.Supuestos'!$B$16)^MAX(0,A15-1)+'1.Supuestos'!$B$6*107360000/1000000000000*A15 -> 341.9019 | C15: =B15*'1.Supuestos'!$B$20 -> 25.642643 | D15: =IF(A15>=1,'1.Supuestos'!$B$24*(1+'1.Supuestos'!$B$16)^(A15-1),0) -> 3.9524023 | E15: =IF(A15>=2,'1.Supuestos'!$B$8*O15/1000000000000,0) -> 1.3434012 | F15: =IF(A15>=3,('1.Supuestos'!$B$9+'1.Supuestos'!$B$10)*O15/1000000000000,0) -> 1.2279569 | G15: =IF(A15>=4,'1.Supuestos'!$B$11*O15/1000000000000,0)+IF(A15>=5,'1.Supuestos'!$B$12*O15/1000000000000,0) -> 6.1397844 | H15: =IF(A15>=5,'1.Supuestos'!$B$13*O15/1000000000000,0) -> 1.9490991 | I15: =IF(A15>=2,('1.Supuestos'!$B$25+'1.Supuestos'!$B$26)*MIN(1,(A15-1)/5)*(1+'1.Supuestos'!$B$16)^(A15-1),0) -> 3.4345013 | J15: =SUM(D15:I15) -> 18.047145 | K15: =K14+J15 -> 121.25172 | L15: =C15+K15 -> 146.89436 | M15: ='1.Supuestos'!$B$36*(1+'1.Supuestos'!$B$37)^(A15-1) -> 599.6229 | N15: =L15/M15 -> 0.2449779 | O15: ='1.Supuestos'!$B$23*12*(1+'1.Supuestos'!$B$16)^(A15-1) -> 4093189.6 | P15: =IF(A15>=1,'1.Supuestos'!$B$28,0)+IF(A15>=2,'1.Supuestos'!$B$29,0)+IF(A15>=3,'1.Supuestos'!$B$30+'1.Supuestos'!$B$31,0)+IF(A15>=4,'1.Supuestos'!$B$33*0.5,0)+IF(A15>=5,'1.Supuestos'!$B$33*0.5+'1.Supuestos'!$B$32,0) -> 203.6
A16: 11 | B16: =P16*(1+'1.Supuestos'!$B$16)^MAX(0,A16-1)+'1.Supuestos'!$B$6*107360000/1000000000000*A16 -> 358.05551 | C16: =B16*'1.Supuestos'!$B$20 -> 26.854163 | D16: =IF(A16>=1,'1.Supuestos'!$B$24*(1+'1.Supuestos'!$B$16)^(A16-1),0) -> 4.0907364 | E16: =IF(A16>=2,'1.Supuestos'!$B$8*O16/1000000000000,0) -> 1.3904202 | F16: =IF(A16>=3,('1.Supuestos'!$B$9+'1.Supuestos'!$B$10)*O16/1000000000000,0) -> 1.2709354 | G16: =IF(A16>=4,'1.Supuestos'!$B$11*O16/1000000000000,0)+IF(A16>=5,'1.Supuestos'!$B$12*O16/1000000000000,0) -> 6.3546769 | H16: =IF(A16>=5,'1.Supuestos'!$B$13*O16/1000000000000,0) -> 2.0173176 | I16: =IF(A16>=2,('1.Supuestos'!$B$25+'1.Supuestos'!$B$26)*MIN(1,(A16-1)/5)*(1+'1.Supuestos'!$B$16)^(A16-1),0) -> 3.5547089 | J16: =SUM(D16:I16) -> 18.678795 | K16: =K15+J16 -> 139.93051 | L16: =C16+K16 -> 166.78468 | M16: ='1.Supuestos'!$B$36*(1+'1.Supuestos'!$B$37)^(A16-1) -> 634.40103 | N16: =L16/M16 -> 0.26290102 | O16: ='1.Supuestos'!$B$23*12*(1+'1.Supuestos'!$B$16)^(A16-1) -> 4236451.3 | P16: =IF(A16>=1,'1.Supuestos'!$B$28,0)+IF(A16>=2,'1.Supuestos'!$B$29,0)+IF(A16>=3,'1.Supuestos'!$B$30+'1.Supuestos'!$B$31,0)+IF(A16>=4,'1.Supuestos'!$B$33*0.5,0)+IF(A16>=5,'1.Supuestos'!$B$33*0.5+'1.Supuestos'!$B$32,0) -> 203.6
A17: 12 | B17: =P17*(1+'1.Supuestos'!$B$16)^MAX(0,A17-1)+'1.Supuestos'!$B$6*107360000/1000000000000*A17 -> 374.54903 | C17: =B17*'1.Supuestos'!$B$20 -> 28.091178 | D17: =IF(A17>=1,'1.Supuestos'!$B$24*(1+'1.Supuestos'!$B$16)^(A17-1),0) -> 4.2339122 | E17: =IF(A17>=2,'1.Supuestos'!$B$8*O17/1000000000000,0) -> 1.439085 | F17: =IF(A17>=3,('1.Supuestos'!$B$9+'1.Supuestos'!$B$10)*O17/1000000000000,0) -> 1.3154181 | G17: =IF(A17>=4,'1.Supuestos'!$B$11*O17/1000000000000,0)+IF(A17>=5,'1.Supuestos'!$B$12*O17/1000000000000,0) -> 6.5770906 | H17: =IF(A17>=5,'1.Supuestos'!$B$13*O17/1000000000000,0) -> 2.0879237 | I17: =IF(A17>=2,('1.Supuestos'!$B$25+'1.Supuestos'!$B$26)*MIN(1,(A17-1)/5)*(1+'1.Supuestos'!$B$16)^(A17-1),0) -> 3.6791237 | J17: =SUM(D17:I17) -> 19.332553 | K17: =K16+J17 -> 159.26307 | L17: =C17+K17 -> 187.35424 | M17: ='1.Supuestos'!$B$36*(1+'1.Supuestos'!$B$37)^(A17-1) -> 671.19629 | N17: =L17/M17 -> 0.2791348 | O17: ='1.Supuestos'!$B$23*12*(1+'1.Supuestos'!$B$16)^(A17-1) -> 4384727.1 | P17: =IF(A17>=1,'1.Supuestos'!$B$28,0)+IF(A17>=2,'1.Supuestos'!$B$29,0)+IF(A17>=3,'1.Supuestos'!$B$30+'1.Supuestos'!$B$31,0)+IF(A17>=4,'1.Supuestos'!$B$33*0.5,0)+IF(A17>=5,'1.Supuestos'!$B$33*0.5+'1.Supuestos'!$B$32,0) -> 203.6
A18: 13 | B18: =P18*(1+'1.Supuestos'!$B$16)^MAX(0,A18-1)+'1.Supuestos'!$B$6*107360000/1000000000000*A18 -> 391.39438 | C18: =B18*'1.Supuestos'!$B$20 -> 29.354578 | D18: =IF(A18>=1,'1.Supuestos'!$B$24*(1+'1.Supuestos'!$B$16)^(A18-1),0) -> 4.3820991 | E18: =IF(A18>=2,'1.Supuestos'!$B$8*O18/1000000000000,0) -> 1.4894529 | F18: =IF(A18>=3,('1.Supuestos'!$B$9+'1.Supuestos'!$B$10)*O18/1000000000000,0) -> 1.3614577 | G18: =IF(A18>=4,'1.Supuestos'!$B$11*O18/1000000000000,0)+IF(A18>=5,'1.Supuestos'!$B$12*O18/1000000000000,0) -> 6.8072887 | H18: =IF(A18>=5,'1.Supuestos'!$B$13*O18/1000000000000,0) -> 2.161001 | I18: =IF(A18>=2,('1.Supuestos'!$B$25+'1.Supuestos'!$B$26)*MIN(1,(A18-1)/5)*(1+'1.Supuestos'!$B$16)^(A18-1),0) -> 3.807893 | J18: =SUM(D18:I18) -> 20.009193 | K18: =K17+J18 -> 179.27226 | L18: =C18+K18 -> 208.62684 | M18: ='1.Supuestos'!$B$36*(1+'1.Supuestos'!$B$37)^(A18-1) -> 710.12567 | N18: =L18/M18 -> 0.29378861 | O18: ='1.Supuestos'!$B$23*12*(1+'1.Supuestos'!$B$16)^(A18-1) -> 4538192.5 | P18: =IF(A18>=1,'1.Supuestos'!$B$28,0)+IF(A18>=2,'1.Supuestos'!$B$29,0)+IF(A18>=3,'1.Supuestos'!$B$30+'1.Supuestos'!$B$31,0)+IF(A18>=4,'1.Supuestos'!$B$33*0.5,0)+IF(A18>=5,'1.Supuestos'!$B$33*0.5+'1.Supuestos'!$B$32,0) -> 203.6
... A35: 30 | B35: =P35*(1+'1.Supuestos'!$B$16)^MAX(0,A35-1)+'1.Supuestos'!$B$6*107360000/1000000000000*A35 -> 745.38636 | C35: =B35*'1.Supuestos'!$B$20 -> 55.903977 | D35: =IF(A35>=1,'1.Supuestos'!$B$24*(1+'1.Supuestos'!$B$16)^(A35-1),0) -> 7.8644461 | E35: =IF(A35>=2,'1.Supuestos'!$B$8*O35/1000000000000,0) -> 2.6730848 | F35: =IF(A35>=3,('1.Supuestos'!$B$9+'1.Supuestos'!$B$10)*O35/1000000000000,0) -> 2.4433749 | G35: =IF(A35>=4,'1.Supuestos'!$B$11*O35/1000000000000,0)+IF(A35>=5,'1.Supuestos'!$B$12*O35/1000000000000,0) -> 12.216875 | H35: =IF(A35>=5,'1.Supuestos'!$B$13*O35/1000000000000,0) -> 3.8782957 | I35: =IF(A35>=2,('1.Supuestos'!$B$25+'1.Supuestos'!$B$26)*MIN(1,(A35-1)/5)*(1+'1.Supuestos'!$B$16)^(A35-1),0) -> 6.8339325 | J35: =SUM(D35:I35) -> 35.910009 | K35: =K34+J35 -> 649.48211 | L35: =C35+K35 -> 705.38608 | M35: ='1.Supuestos'!$B$36*(1+'1.Supuestos'!$B$37)^(A35-1) -> 1851.7893 | N35: =L35/M35 -> 0.38092136 | O35: ='1.Supuestos'!$B$23*12*(1+'1.Supuestos'!$B$16)^(A35-1) -> 8144583.1 | P35: =IF(A35>=1,'1.Supuestos'!$B$28,0)+IF(A35>=2,'1.Supuestos'!$B$29,0)+IF(A35>=3,'1.Supuestos'!$B$30+'1.Supuestos'!$B$31,0)+IF(A35>=4,'1.Supuestos'!$B$33*0.5,0)+IF(A35>=5,'1.Supuestos'!$B$33*0.5+'1.Supuestos'!$B$32,0) -> 203.6
A38: Nota metodológica:
A39: (1) Todos los parámetros están en la hoja 1.Supuestos con fuente citada. (2) Capital prestable = 7,5% del fondo total (Regla 25% × 30% del libro p.3511). (3) Ahorro uniformados 100% desde año 1 según libro p.2495 (universo completo: 176.536 personas). (4) PGU crece con IPC 3,5% + salto Ley 21.735 desde sep.2026 ($231.732 → $250.275). (5) Calendario de incorporación: Año 1 Unif / Año 2 Civ.AFP / Año 3 Prof+PO / Año 4 Olvid t1 / Año 5 Olvid t2+SinAhorro. (6) PIB base 2026: $361 billones (DIPRES IFP 4T 2025). Crecimiento: 2,3% real + 3,5% IPC = 5,8% nominal.

Sheet 3.Comparación Tabla A
A1: COMPARACIÓN: TABLA A DEL LIBRO vs TABLA C CALCULADA
A2: La Tabla C reproduce con aritmética transparente los órdenes de magnitud de la Tabla A del libro.
A4: Concepto | B4: Año | C4: Tabla A libro | D4: Tabla C (link) | E4: Diferencia | F4: Observación
A5: Capital prestable al fisco | B5: 5 | C5: 14.6 | D5: ='2.Tabla C (30 años)'!C10 -> 19.938276 | E5: =D5-C5 -> 5.3382762 | F5: Tabla C más alta por aplicar 7,5% fiel a regla del libro
A6: Ahorro fiscal acumulado | B6: 5 | C6: 38.6 | D6: ='2.Tabla C (30 años)'!K10 -> 36.915977 | E6: =D6-C6 -> -1.6840227 | F6: Muy cercano (dif < 5%)
A7: BENEFICIO TOTAL | B7: 5 | C7: 53.2 | D7: ='2.Tabla C (30 años)'!L10 -> 56.854254 | E7: =D7-C7 -> 3.6542536 | F7: Coherencia con Tabla A
A9: Capital prestable al fisco | B9: 10 | C9: 24.2 | D9: ='2.Tabla C (30 años)'!C15 -> 25.642643 | E9: =D9-C9 -> 1.4426426 | F9: Coherente con Tabla A
A10: Ahorro fiscal acumulado | B10: 10 | C10: 128.9 | D10: ='2.Tabla C (30 años)'!K15 -> 121.25172 | E10: =D10-C10 -> -7.6482832 | F10: Diferencia < 6% (aceptable)
A11: BENEFICIO TOTAL | B11: 10 | C11: 153.1 | D11: ='2.Tabla C (30 años)'!L15 -> 146.89436 | E11: =D11-C11 -> -6.2056406 | F11: Coherencia con Tabla A
A13: EXTENSIÓN — AÑOS 20 Y 30 (no presentes en Tabla A del libro)
A14: Capital prestable al fisco | B14: 20 | D14: ='2.Tabla C (30 años)'!C25 -> 39.018995 | E14: — | F14: Proyección sobre Tabla A
A15: Ahorro fiscal acumulado | B15: 20 | D15: ='2.Tabla C (30 años)'!K25 -> 340.38001
A16: BENEFICIO TOTAL | B16: 20 | D16: ='2.Tabla C (30 años)'!L25 -> 379.399
A18: Capital prestable al fisco | B18: 30 | D18: ='2.Tabla C (30 años)'!C35 -> 55.903977
A19: Ahorro fiscal acumulado | B19: 30 | D19: ='2.Tabla C (30 años)'!K35 -> 649.48211
A20: BENEFICIO TOTAL | B20: 30 | D20: ='2.Tabla C (30 años)'!L35 -> 705.38608
A23: CONCLUSIÓN
A24: La Tabla C reproduce los órdenes de magnitud de la Tabla A del libro (diferencias < 7%) con la ventaja de declarar explícitamente todos los supuestos usados. Esto convierte los números en verificables y defendibles ante cualquier crítico técnico. Además, extiende la proyección a 30 años, mostrando que el beneficio al Estado crece de forma progresiva desde ~$7 B al año 1 hasta ~$700 B al año 30 (≈38% del PIB).
A26: NOTA — CIFRAS CONSERVADORAS
A27: Las cifras de esta Tabla C son deliberadamente conservadoras: el modelo no capitaliza el stock del fondo AFJ al 5% real año a año, solo incorpora el crecimiento por IPC y por cohorte anual de nuevos jubilados. La cifra real del beneficio al año 30 podría ser entre 30% y 50% superior. Se prefiere errar por defecto — ver hoja 4.Metodología para explicación completa. Herramienta complementaria: Calculadora Interactiva v5.0 en 52daneridanilo47-cpu.github.io/modelorentista/

Sheet 4.Metodología
A1: METODOLOGÍA — MODELO RENTISTA vs PROYECCIONES DIPRES 2026
A2: Comparación transparente de enfoques: dos herramientas complementarias, no rivales.
A4: Dimensión | B4: DIPRES 2026 (Modelo Oficial) | C4: Tabla C (Modelo Rentista)
A5: Naturaleza | B5: Descriptivo-actuarial: proyecta qué pasará bajo reglas vigentes (AFP + PGU + Ley 21.735) | C5: Prescriptivo-político: proyecta qué pasaría bajo reglas alternativas (AFJ + Modelo Rentista)
A6: Método | B6: Microsimulación dinámica con cadenas markovianas de decremento múltiple (5,5M individuos, 77 años) | C6: Proyección determinística con cohorte fija, supuestos declarados, aritmética ×240
A7: Horizonte | B7: 75 años (2025-2100) | C7: 30 años (2026-2055)
A8: Lector objetivo | B8: Actuarios, Ministerio de Hacienda, DIPRES, Consejo Fiscal Autónomo | C8: Político, uniformados, dirigentes sindicales, ciudadano común
A9: Parámetros clave | B9: Tasas de mortalidad RV-2022, densidad cotización, migración, nupcialidad | C9: Cohorte 60k/año, tasa 5% real, IPC 3,5%, fracción prestable 7,5%
A10: Qué mide | B10: Gasto fiscal PGU + BAC + CEV + CAPREDENA/DIPRECA año a año bajo reformas vigentes | C10: Beneficio acumulado Estado (capital prestable + ahorro fiscal sustituido) año a año
A11: Transparencia | B11: Código fuente interno DIPRES; supuestos publicados en Cuadros del informe | C11: Todos los supuestos en hoja 1.Supuestos con fuente citada; todas las fórmulas visibles
A12: Comparabilidad | B12: Referencia para evaluar sostenibilidad del sistema actual | C12: Referencia para evaluar sustitución por modelo alternativo
A13: Citas cruzadas | B13: No cita al Modelo Rentista (no está publicado) | C13: Cita a DIPRES 2026 como contraste metodológico
A15: REFERENCIAS
A16: · DIPRES (marzo 2026). Modelo de Proyecciones del Sistema de Pensiones en Chile: 2025-2100. Dirección de Presupuestos, Ministerio de Hacienda.
A17: · DIPRES (enero 2026). Proyecciones de Gasto Público en Chile 2025-2050. Estudios de Finanzas Públicas 2025/48.
A18: · DIPRES (diciembre 2025). Estimación de Ingresos y Egresos del FAPP. Estudios de Finanzas Públicas.
A19: · DIPRES (febrero 2026). Informe de Finanzas Públicas 4T 2025. Ministerio de Hacienda.
A20: · Daneri Solano, D. (2026). Modelo Rentista. Libro Cap.10-11 (Tablas A y B).
A21: · Banco Central de Chile (2026). Informe de Política Monetaria, marzo 2026.
A22: · Ley N° 21.735 (2025). Reforma del Sistema de Pensiones. Gobierno de Chile.
A23: · INE (2023). Tablas de Mortalidad RV-2022 y Proyecciones de Población.
A24: · CIEDESS (oct.2024). Datos CAPREDENA/DIPRECA.
A25: · Superintendencia de Pensiones (2024). Estadísticas del Sistema de Pensiones.
A27: NOTA METODOLÓGICA — ENFOQUE CONSERVADOR DELIBERADO
... A34: HERRAMIENTAS COMPLEMENTARIAS
A35: Calculadora Interactiva Modelo Rentista (v5.0) | B35: https://52daneridanilo47-cpu.github.io/modelorentista/
A36: Libro Modelo Rentista (Daneri, 2026) | B36: Caps. 10-11 (Tablas A y B) · Bibliografía completa en el libro
A37: Autor | B37: Danilo Daneri Solano · 52daneridanilo47@gmail.com
